Workbook

Sheet 이행현황요약
A1: 대한민국 AI 행동계획 2026 — 이행현황 요약
A2: 출처: 국가AI전략위 행동계획 확정본(’26.2.25) + K-AI2026 대시보드(UNOFFICIAL) 분석 기준
A3: 기준일 | B3: 46206
A5: ■ 총괄 | D5: ■ 위험도별 현황 (기준일 기준)
A6: 실천과제 수 | B6: 99 | D6: 위험도 | E6: 권고 수 | F6: 비중
A7: 정책권고 수 | B7: =COUNTA('★최종안'!$D$2:$D$327) -> 326 | D7: 기한초과 | E7: =COUNTIF('★최종안'!$O$2:$O$327,"기한초과") -> 166 | F7: =E7/SUM($E$7:$E$12) -> 0.50920245
A8: 정책축 | B8: 3 | D8: 긴급 | E8: =COUNTIF('★최종안'!$O$2:$O$327,"긴급") -> 0 | F8: =E8/SUM($E$7:$E$12) -> 0
A9: 전략분야 | B9: 12 | D9: 주의 | E9: =COUNTIF('★최종안'!$O$2:$O$327,"주의") -> 28 | F9: =E9/SUM($E$7:$E$12) -> 0.085889571
D10: 관찰 | E10: =COUNTIF('★최종안'!$O$2:$O$327,"관찰") -> 72 | F10: =E10/SUM($E$7:$E$12) -> 0.2208589
D11: 여유 | E11: =COUNTIF('★최종안'!$O$2:$O$327,"여유") -> 36 | F11: =E11/SUM($E$7:$E$12) -> 0.11042945
D12: 기한없음 | E12: =COUNTIF('★최종안'!$O$2:$O$327,"기한없음") -> 24 | F12: =E12/SUM($E$7:$E$12) -> 0.073619632
D13: 계 | E13: =SUM(E7:E12) -> 326 | F13: =SUM(F7:F12) -> 1
A15: ■ 정책축별 권고 수 | D15: ■ 추진기한별 권고 수
A16: 정책축 | B16: 권고 수 | D16: 기한 | E16: 권고 수
A17: 1. AI 혁신생태계 조성 | B17: =COUNTIF('★최종안'!$A$2:$A$327,"1. AI 혁신생태계 조성*") -> 134 | D17: ’26.1 | E17: =COUNTIF('★최종안'!$H$2:$H$327,"26.1") -> 81
A18: 2. 범국가 AI 기반 대전환 | B18: =COUNTIF('★최종안'!$A$2:$A$327,"2. 범국가 AI 기반 대전환*") -> 114 | D18: ’26.2 | E18: =COUNTIF('★최종안'!$H$2:$H$327,"26.2") -> 85
A19: 3. 글로벌 AI 기본사회 기여 | B19: =COUNTIF('★최종안'!$A$2:$A$327,"3. 글로벌 AI 기본사회 기여*") -> 78 | D19: ’26.3 | E19: =COUNTIF('★최종안'!$H$2:$H$327,"26.3") -> 28
A20: 계 | B20: =SUM(B17:B19) -> 326 | D20: ’26.4 | E20: =COUNTIF('★최종안'!$H$2:$H$327,"26.4") -> 72
D21: ’27.1 | E21: =COUNTIF('★최종안'!$H$2:$H$327,"27.1") -> 11
A22: ■ 주요 부처별 권고 수 (주관 기준, 상위) | D22: ’27.2 | E22: =COUNTIF('★최종안'!$H$2:$H$327,"27.2") -> 6
A23: 부처 | B23: 권고 수 | D23: ’27.4 | E23: =COUNTIF('★최종안'!$H$2:$H$327,"27.4") -> 17
A24: 과기정통부 | B24: =COUNTIF('★최종안'!$I$2:$I$327,"*과기정통부*") -> 121 | D24: ’28.1 | E24: =COUNTIF('★최종안'!$H$2:$H$327,"28.1") -> 1
A25: 복지부 | B25: =COUNTIF('★최종안'!$I$2:$I$327,"*복지부*") -> 17 | D25: ’30.4 | E25: =COUNTIF('★최종안'!$H$2:$H$327,"30.4") -> 1
A26: 산업부 | B26: =COUNTIF('★최종안'!$I$2:$I$327,"*산업부*") -> 31 | D26: 기한없음 | E26: =COUNTIF('★최종안'!$H$2:$H$327,"기한없음") -> 24
A27: 국방부 | B27: =COUNTIF('★최종안'!$I$2:$I$327,"*국방부*") -> 23 | D27: 계 | E27: =SUM(E17:E26) -> 326
A28: 교육부 | B28: =COUNTIF('★최종안'!$I$2:$I$327,"*교육부*") -> 32
A29: 행안부 | B29: =COUNTIF('★최종안'!$I$2:$I$327,"*행안부*") -> 25
A30: 중기부 | B30: =COUNTIF('★최종안'!$I$2:$I$327,"*중기부*") -> 12
A31: 국토부 | B31: =COUNTIF('★최종안'!$I$2:$I$327,"*국토부*") -> 11
A32: 문체부 | B32: =COUNTIF('★최종안'!$I$2:$I$327,"*문체부*") -> 12
A33: 금융위 | B33: =COUNTIF('★최종안'!$I$2:$I$327,"*금융위*") -> 6
A35: ※ 위험도 분류: 기한초과(D<0) / 긴급(D≤34) / 주의(D≤120) / 관찰(D≤240) / 여유(그 외) — K-AI2026 대시보드와 동일 기준
A36: ※ 부처별 수치는 주관 열에 부처명이 포함된 권고 수(공동주관 시 중복 집계될 수 있음)

Sheet ★최종안
A1: 정책축 | B1: 전략분야 | C1: 과제 구분 | D1: 과제 번호 | E1: 과제명 | F1: 분과 구분(안) | G1: 최종안 | H1: 기한 | I1: 주관 | J1: 공동주관 | K1: 협조부처 | L1: 담당 팀 | M1: 기한일자 | N1: D-Day | O1: 위험도 | P1: 이행상태
A2: 1. AI 혁신생태계 조성 | B2: 전략분야 1) AI 고속도로 구축 | C2: 01 GPU, NPU 등 핵심 AI 컴퓨팅 인프라 확충 | D2: 1-1 | E2: 첨단 GPU 확충 및 운영 | F2: 기술혁신·인프라 분과 | G2: 과기정통부는 최소 5만장 이상의 대규모 첨단 GPU를 정부 주도로 ’28년 4분기까지 확충하며, 이를 활용한 정부 글로벌 프론티어 AI 과제 등 대규모 모델 학습 및 서비스를 위한 운영 계획을 ’26년 1분기 내 수립한다. | H2: 26.1 | I2: 과기정통부 | L2: AI인프라지원팀 | M2: =IF($H2="기한없음","",DATE(2000+VALUE(LEFT($H2,2)),VALUE(RIGHT($H2,1))*3+1,1)-1) -> 46112 | N2: =IF($M2="","",$M2-이행현황요약!$B$3) -> -94 | O2: =IF($H2="기한없음","기한없음",IF($N2<0,"기한초과",IF($N2<=34,"긴급",IF($N2<=120,"주의",IF($N2<=240,"관찰","여유"))))) -> 기한초과 | P2: 진행중
A3: 1. AI 혁신생태계 조성 | B3: 전략분야 1) AI 고속도로 구축 | C3: 01 GPU, NPU 등 핵심 AI 컴퓨팅 인프라 확충 | D3: 1-2 | E3: GPU 현황조사 및 배분 | F3: 기술혁신·인프라 분과 | G3: 과기정통부는 국내 GPU 자원에 대한 현황 조사를 ’26년 2분기 내 시행하며, 기보유분을 포함해 정부에서 확보한 GPU 배분 계획을 ’26년 4분기까지 수립한다. | H3: 26.2 | I3: 과기정통부 | L3: AI인프라지원팀 | M3: =IF($H3="기한없음","",DATE(2000+VALUE(LEFT($H3,2)),VALUE(RIGHT($H3,1))*3+1,1)-1) -> 46203 | N3: =IF($M3="","",$M3-이행현황요약!$B$3) -> -3 | O3: =IF($H3="기한없음","기한없음",IF($N3<0,"기한초과",IF($N3<=34,"긴급",IF($N3<=120,"주의",IF($N3<=240,"관찰","여유"))))) -> 기한초과 | P3: 진행중
A4: 1. AI 혁신생태계 조성 | B4: 전략분야 1) AI 고속도로 구축 | C4: 01 GPU, NPU 등 핵심 AI 컴퓨팅 인프라 확충 | D4: 1-3 | E4: 국산 AI반도체 도입 및 생태계 고도화 | F4: 기술혁신·인프라 분과 | G4: 과기정통부는 산업부와 협의하여 국산 AI 반도체 기술 경쟁력 강화 및 활성화를 위해 국산 AI 반도체 도입 방안을 ’26년 4분기까지 마련하고 해당 물량을 ’30년 4분기까지 단계적으로 확보한다. 과기정통부는 또한 국산 AI 반도체의 객관적 검증을 위한 평가 체계 수립, 인재 양성 및 차세대 AI 반도체 연구 거점 조성, 부처 간 정책 연계·협력 강화를 위해 산업부와 협의하여 AI 반도체 총괄 협의체를 ’26년 4분기까지 구성하고 국가 차원의 일관된 AI 반도체 생태계 고도화를 추진한다. | H4: 26.4 | I4: 과기정통부 | K4: 산업부 | L4: AI인프라지원팀 | M4: =IF($H4="기한없음","",DATE(2000+VALUE(LEFT($H4,2)),VALUE(RIGHT($H4,1))*3+1,1)-1) -> 46387 | N4: =IF($M4="","",$M4-이행현황요약!$B$3) -> 181 | O4: =IF($H4="기한없음","기한없음",IF($N4<0,"기한초과",IF($N4<=34,"긴급",IF($N4<=120,"주의",IF($N4<=240,"관찰","여유"))))) -> 관찰 | P4: 진행중
A5: 1. AI 혁신생태계 조성 | B5: 전략분야 1) AI 고속도로 구축 | C5: 02 지속가능한 AI 데이터센터 생태계 구축 | D5: 2-1 | E5: 대형 AI데이터센터 생태계 활성화 | F5: 기술혁신·인프라 분과 | G5: 과기정통부는 기후부, 국토부, 문체부, 해수부 등과 협력하여 급변하는 기술 및 수요 변화에 부응하고, 민간 중심 대형 AI 데이터센터 생태계를 활성화할 수 있도록 데이터센터 구축 종합 계획을 ’26년 2분기까지 수립한다. 또한 재정경제부와 협력하여 AI 데이터센터 민간투자 촉진을 위한 세제 혜택 방안 등을 ’26년 1분기까지 완료한다. | H5: 26.1 | I5: 과기정통부 | K5: 산업부 | L5: AI인프라지원팀 | M5: =IF($H5="기한없음","",DATE(2000+VALUE(LEFT($H5,2)),VALUE(RIGHT($H5,1))*3+1,1)-1) -> 46112 | N5: =IF($M5="","",$M5-이행현황요약!$B$3) -> -94 | O5: =IF($H5="기한없음","기한없음",IF($N5<0,"기한초과",IF($N5<=34,"긴급",IF($N5<=120,"주의",IF($N5<=240,"관찰","여유"))))) -> 기한초과 | P5: 진행중
A6: 1. AI 혁신생태계 조성 | B6: 전략분야 1) AI 고속도로 구축 | C6: 02 지속가능한 AI 데이터센터 생태계 구축 | D6: 2-2 | E6: 강소형 AI데이터센터 확산 | F6: 기술혁신·인프라 분과 | G6: 과기정통부는 행안부와 협조하여 공공 및 산업 AX 분야의 수요를 기반으로 한 강소형 AI 데이터센터 확산 방안을 ’26년 4분기 내 마련한다. | H6: 26.4 | I6: 과기정통부 | K6: 행안부 | L6: AI인프라지원팀 | M6: =IF($H6="기한없음","",DATE(2000+VALUE(LEFT($H6,2)),VALUE(RIGHT($H6,1))*3+1,1)-1) -> 46387 | N6: =IF($M6="","",$M6-이행현황요약!$B$3) -> 181 | O6: =IF($H6="기한없음","기한없음",IF($N6<0,"기한초과",IF($N6<=34,"긴급",IF($N6<=120,"주의",IF($N6<=240,"관찰","여유"))))) -> 관찰 | P6: 진행중
A7: 1. AI 혁신생태계 조성 | B7: 전략분야 1) AI 고속도로 구축 | C7: 02 지속가능한 AI 데이터센터 생태계 구축 | D7: 2-3 | E7: AI 데이터센터 전력·에너지 안정성 확보 | F7: 기술혁신·인프라 분과 | G7: 기후부는 전력 계통 안정성 확보를 최우선 목표로, 전력 계통 영향 평가 제도의 지역 간 차등 적용을 통해 비수도권 데이터센터 입지 유인을 강화하고, AI 데이터센터 전력 수요를 ｢전력수급기본계획｣에 합리적으로 반영한다. 또한 기후부는 과기정통부와 협력하여 해외기업의 비수도권 AI 데이터센터 등 투자 유치를 위한 전력·에너지 관련 인센티브 제공 방안 및 재생에너지 발전소-데이터센터 간 연계를 유도·활성화할 수 있는 지원방안을 ’26년 2분기까지 수립한다. | H7: 26.2 | I7: 기후부 | K7: 과기정통부 | L7: AI인프라지원팀 | M7: =IF($H7="기한없음","",DATE(2000+VALUE(LEFT($H7,2)),VALUE(RIGHT($H7,1))*3+1,1)-1) -> 46203 | N7: =IF($M7="","",$M7-이행현황요약!$B$3) -> -3 | O7: =IF($H7="기한없음","기한없음",IF($N7<0,"기한초과",IF($N7<=34,"긴급",IF($N7<=120,"주의",IF($N7<=240,"관찰","여유"))))) -> 기한초과 | P7: 진행중
A8: 1. AI 혁신생태계 조성 | B8: 전략분야 1) AI 고속도로 구축 | C8: 03 AI 서비스 기반 고도화를 통한 접근성 제고 | D8: 3-1 | E8: AI시대 네트워크 고도화 | F8: 기술혁신·인프라 분과 | G8: 과기정통부는 ’30년까지 피지컬AI와 에이전틱 AI서비스를 뒷받침하는 AI-RAN(Radio Access Network) 상용화, 위성통신망 연동, 초저지연·초대역폭 서비스 수요에 대응한 지능형 6G 용량 확충 및 트래픽 예측 기반의 운용방안 등을 포함하여 AI 시대에 대응한 네트워크 고도화를 할 수 있도록 관련 계획을 ’26년 1분기 내 수립한다. 또한 AI시대 트래픽 폭증과 초실감 AI서비스 등 국내외 수요 대응을 위한 백본망·데이터센터 네트워크 고도화와 함께, 해저케이블 인프라 확충 등을 ’30년까지 추진한다. | H8: 26.1 | I8: 과기정통부 | L8: AI인프라지원팀 | M8: =IF($H8="기한없음","",DATE(2000+VALUE(LEFT($H8,2)),VALUE(RIGHT($H8,1))*3+1,1)-1) -> 46112 | N8: =IF($M8="","",$M8-이행현황요약!$B$3) -> -94 | O8: =IF($H8="기한없음","기한없음",IF($N8<0,"기한초과",IF($N8<=34,"긴급",IF($N8<=120,"주의",IF($N8<=240,"관찰","여유"))))) -> 기한초과 | P8: 진행중
A9: 1. AI 혁신생태계 조성 | B9: 전략분야 1) AI 고속도로 구축 | C9: 03 AI 서비스 기반 고도화를 통한 접근성 제고 | D9: 3-2 | E9: 데이터센터 자원 등 접근성 제고 | F9: 기술혁신·인프라 분과 | G9: 과기정통부는 국가 주도 대형 AI 데이터센터 및 지역 AI 데이터센터 자원의 개방 및 접근성을 높이기 위한 클라우드 서비스 구축 지원 프로그램을 마련하여 ’26년부터 실시한다. 또한, 중기부는 제조 중소기업 대상 바우처 사업계획을 수립하여 ’26년에 시행하고, 복지부는 지역·필수의료 확충 지원을 위해 보건소 및 가칭‘AI 중심병원’대상 바우처 사업계획 및 시스템 개선계획을 수립하여 ’26년에 시행한다. | H9: 26.4 | I9: 과기정통부, 중기부, 복지부 | J9: O | L9: AI인프라지원팀 | M9: =IF($H9="기한없음","",DATE(2000+VALUE(LEFT($H9,2)),VALUE(RIGHT($H9,1))*3+1,1)-1) -> 46387 | N9: =IF($M9="","",$M9-이행현황요약!$B$3) -> 181 | O9: =IF($H9="기한없음","기한없음",IF($N9<0,"기한초과",IF($N9<=34,"긴급",IF($N9<=120,"주의",IF($N9<=240,"관찰","여유"))))) -> 관찰 | P9: 진행중
A10: 1. AI 혁신생태계 조성 | B10: 전략분야 1) AI 고속도로 구축 | C10: 04 국가데이터 통합플랫폼 기반 민간·공공 데이터 소재 연계 및 품질 고도화 | D10: 4-1 | E10: 국가데이터 통합플랫폼 구축 | F10: 데이터 분과 | G10: 과기정통부는 AI개발 활용에 필수인 모든 민간･공공데이터의 소재 정보가 한 곳에 연계될 수 있도록 하는 표준화된 ‘국가데이터 통합플랫폼’을 ’26년 4분기까지 구축･운영할 수 있도록, 관련 계획을 ’26년 1분기 내로 마련한다. 또한 과기정통부는 ‘국가데이터 통합플랫폼’에 연계할 하위 데이터 플랫폼을 지정하고 해당 부처가 표준화 연계를 의무화하기 위한 법령안을 ’26년 2분기 이내 발의하여 법제화를 추진하며, 관계부처는 이에 따른다. | H10: 26.1 | I10: 과기정통부 | L10: AI데이터규제혁신팀 | M10: =IF($H10="기한없음","",DATE(2000+VALUE(LEFT($H10,2)),VALUE(RIGHT($H10,1))*3+1,1)-1) -> 46112 | N10: =IF($M10="","",$M10-이행현황요약!$B$3) -> -94 | O10: =IF($H10="기한없음","기한없음",IF($N10<0,"기한초과",IF($N10<=34,"긴급",IF($N10<=120,"주의",IF($N10<=240,"관찰","여유"))))) -> 기한초과 | P10: 진행중
A11: 1. AI 혁신생태계 조성 | B11: 전략분야 1) AI 고속도로 구축 | C11: 04 국가데이터 통합플랫폼 기반 민간·공공 데이터 소재 연계 및 품질 고도화 | D11: 4-2 | E11: AI 학습데이터 등록·연계 제도화 | F11: 데이터 분과 | G11: 과기정통부는 정부 사업을 통해 만들어진 AI 학습데이터 및 산출데이터는 비민감, 비독점 범위내에서 AI hub에 등록·연계하고 해당 데이터의 소재정보는 국가데이터 통합플랫폼에 등록·연계되도록 의무화하기 위한 법률 제･개정안을 ’26년 2분기까지 발의하여 법제화를 추진하고, 기획예산처는 그 이전에라도 제도가 동작하도록 관련 예산안 편성지침 및 세부지침을 과기정통부와 협의하여 ’26년 4분기 내 제･개정하고 이를 ’27년도부터 모든 사업에 적용한다. | H11: 26.2 | I11: 과기정통부, 기획처 | J11: O | L11: AI데이터규제혁신팀 | M11: =IF($H11="기한없음","",DATE(2000+VALUE(LEFT($H11,2)),VALUE(RIGHT($H11,1))*3+1,1)-1) -> 46203 | N11: =IF($M11="","",$M11-이행현황요약!$B$3) -> -3 | O11: =IF($H11="기한없음","기한없음",IF($N11<0,"기한초과",IF($N11<=34,"긴급",IF($N11<=120,"주의",IF($N11<=240,"관찰","여유"))))) -> 기한초과 | P11: 진행중
A12: 1. AI 혁신생태계 조성 | B12: 전략분야 1) AI 고속도로 구축 | C12: 04 국가데이터 통합플랫폼 기반 민간·공공 데이터 소재 연계 및 품질 고도화 | D12: 4-3 | E12: 국가데이터 통합플랫폼 공공데이터 품질기준 상향 및 민간데이터 연계 | F12: 데이터 분과 | G12: 행안부는 ‘국가데이터 통합플랫폼’의 표준에 따라 최종적으로 연결되는 공공데이터들이 AI학습 및 AI서비스 개발에 원활히 활용될 수 있도록 상향된 데이터 품질 및 평가 기준을 ’26년 1분기까지 마련한다. 이 품질기준은 데이터의 적절한 현행화 절차를 반드시 포함해야 한다. 과기정통부는 민간 데이터 플랫폼의 국가데이터 통합플랫폼 연계와 민간 데이터 플랫폼 내 데이터의 AI학습 및 AI서비스 개발 최적화를 위한 인센티브 정책을 ’26년 1분기까지 수립한다. | H12: 26.1 | I12: 행안부, 과기정통부 | J12: O | L12: AI데이터규제혁신팀 | M12: =IF($H12="기한없음","",DATE(2000+VALUE(LEFT($H12,2)),VALUE(RIGHT($H12,1))*3+1,1)-1) -> 46112 | N12: =IF($M12="","",$M12-이행현황요약!$B$3) -> -94 | O12: =IF($H12="기한없음","기한없음",IF($N12<0,"기한초과",IF($N12<=34,"긴급",IF($N12<=120,"주의",IF($N12<=240,"관찰","여유"))))) -> 기한초과 | P12: 진행중
A13: 1. AI 혁신생태계 조성 | B13: 전략분야 1) AI 고속도로 구축 | C13: 05 AI 데이터 공유 생태계 활성화 | D13: 5-1 | E13: AI 학습데이터 공유 활성화 | F13: 데이터 분과 | G13: 과기정통부는 국세청 등 관계 부처와 협력하여 AI 학습·평가에 활용될 수 있는 데이터의 대외 공개 또는 기부 등을 통해 데이터 공유를 활성화할 수 있는 방안을 ’26년 2분기 이내로 마련한다. 동 방안에는 기업이나 개인 등 공유 주체에 대해 세액공제, 맞춤형 컨설팅, 정부 인프라 우선 이용, 정부 사업 가점 등의 혜택을 부여하는 것을 포함한다. 또한 신설된 제도의 정착과 데이터 공유에 대한 사회적 인식이 확산될 수 있도록 적극적인 인식 제고 활동을 ’26년부터 수행한다. | H13: 26.2 | I13: 과기정통부 | K13: 국세청 | L13: AI데이터규제혁신팀 | M13: =IF($H13="기한없음","",DATE(2000+VALUE(LEFT($H13,2)),VALUE(RIGHT($H13,1))*3+1,1)-1) -> 46203 | N13: =IF($M13="","",$M13-이행현황요약!$B$3) -> -3 | O13: =IF($H13="기한없음","기한없음",IF($N13<0,"기한초과",IF($N13<=34,"긴급",IF($N13<=120,"주의",IF($N13<=240,"관찰","여유"))))) -> 기한초과 | P13: 진행중
A14: 1. AI 혁신생태계 조성 | B14: 전략분야 1) AI 고속도로 구축 | C14: 05 AI 데이터 공유 생태계 활성화 | D14: 5-2 | E14: 데이터 가치평가·품질인증 제도 통합 및 활용도 제고 | F14: 데이터 분과 | G14: 과기정통부는 행안부 등 관계 부처와 협력하여 데이터 가치 평가와 품질 인증 제도가 범부처적으로 통합 및 활용되도록 하며, 관계 부처와 협력하여 ’26년 연내 단계적으로 산업 도메인별로 특화된 데이터 가치 평가 및 품질 인증 모델을 마련하고 기업의 활용을 제고하는 방안을 수립한다. | H14: 26.4 | I14: 과기정통부 | K14: 행안부 | L14: AI데이터규제혁신팀 | M14: =IF($H14="기한없음","",DATE(2000+VALUE(LEFT($H14,2)),VALUE(RIGHT($H14,1))*3+1,1)-1) -> 46387 | N14: =IF($M14="","",$M14-이행현황요약!$B$3) -> 181 | O14: =IF($H14="기한없음","기한없음",IF($N14<0,"기한초과",IF($N14<=34,"긴급",IF($N14<=120,"주의",IF($N14<=240,"관찰","여유"))))) -> 관찰 | P14: 진행중
A15: 1. AI 혁신생태계 조성 | B15: 전략분야 1) AI 고속도로 구축 | C15: 05 AI 데이터 공유 생태계 활성화 | D15: 5-3 | E15: 민간 데이터 공유 초기 지원 | F15: 데이터 분과 | G15: 과기정통부는 관계 부처와 협력하여 공유용 데이터 구축 비용 지원 등 민간 데이터 공유 활성화를 위한 초기 지원 사업을 기획하여 ’26년 3분기부터 시행한다. | H15: 26.3 | I15: 과기정통부 | L15: AI데이터규제혁신팀 | M15: =IF($H15="기한없음","",DATE(2000+VALUE(LEFT($H15,2)),VALUE(RIGHT($H15,1))*3+1,1)-1) -> 46295 | N15: =IF($M15="","",$M15-이행현황요약!$B$3) -> 89 | O15: =IF($H15="기한없음","기한없음",IF($N15<0,"기한초과",IF($N15<=34,"긴급",IF($N15<=120,"주의",IF($N15<=240,"관찰","여유"))))) -> 주의 | P15: 진행중
A16: 1. AI 혁신생태계 조성 | B16: 전략분야 1) AI 고속도로 구축 | C16: 06 보건의료 AI 고도화와 AX 전환에 필요한 학습데이터 확충 | D16: 6-1 | E16: 다기관 의료데이터 확보·활용 | F16: AI기본의료 소그룹 | G16: 복지부는 AI학습을 위한 다기관 의료데이터를 확보하고 공공데이터와 민간 의료데이터를 결합 활용할 방안(입법 계획을 포함하여)을 ’26년 2분기까지 마련한다. | H16: 26.2 | I16: 복지부 | L16: AI인재양성지원팀 | M16: =IF($H16="기한없음","",DATE(2000+VALUE(LEFT($H16,2)),VALUE(RIGHT($H16,1))*3+1,1)-1) -> 46203 | N16: =IF($M16="","",$M16-이행현황요약!$B$3) -> -3 | O16: =IF($H16="기한없음","기한없음",IF($N16<0,"기한초과",IF($N16<=34,"긴급",IF($N16<=120,"주의",IF($N16<=240,"관찰","여유"))))) -> 기한초과 | P16: 진행중
A17: 1. AI 혁신생태계 조성 | B17: 전략분야 1) AI 고속도로 구축 | C17: 06 보건의료 AI 고도화와 AX 전환에 필요한 학습데이터 확충 | D17: 6-2 | E17: 보건의료 빅데이터 플랫폼 활용 | F17: AI기본의료 소그룹 | G17: 복지부는 ‘독자 AI 파운데이션모델’ 및 보건의료 특화 파운데이션 모델 개발을 위해 보건의료 학습데이터를 이용할 수 있도록 보건의료 빅데이터 플랫폼의 활용 방안을 ’26년 1분기까지 마련한다. | H17: 26.1 | I17: 복지부 | L17: AI인재양성지원팀 | M17: =IF($H17="기한없음","",DATE(2000+VALUE(LEFT($H17,2)),VALUE(RIGHT($H17,1))*3+1,1)-1) -> 46112 | N17: =IF($M17="","",$M17-이행현황요약!$B$3) -> -94 | O17: =IF($H17="기한없음","기한없음",IF($N17<0,"기한초과",IF($N17<=34,"긴급",IF($N17<=120,"주의",IF($N17<=240,"관찰","여유"))))) -> 기한초과 | P17: 진행중
A18: 1. AI 혁신생태계 조성 | B18: 전략분야 1) AI 고속도로 구축 | C18: 06 보건의료 AI 고도화와 AX 전환에 필요한 학습데이터 확충 | D18: 6-3 | E18: 군 의료데이터 통합·활용 | F18: AI기본의료 소그룹 | G18: 국방부는 군 보유 의료데이터의 통합 및 활용 방안과 AI시범 사업에 대한 계획을 복지부와 협력하여 ’26년 2분기까지 마련한다. | H18: 26.2 | I18: 국방부 | K18: 복지부 | L18: AI인재양성지원팀 | M18: =IF($H18="기한없음","",DATE(2000+VALUE(LEFT($H18,2)),VALUE(RIGHT($H18,1))*3+1,1)-1) -> 46203 | N18: =IF($M18="","",$M18-이행현황요약!$B$3) -> -3 | O18: =IF($H18="기한없음","기한없음",IF($N18<0,"기한초과",IF($N18<=34,"긴급",IF($N18<=120,"주의",IF($N18<=240,"관찰","여유"))))) -> 기한초과 | P18: 진행중
A19: 1. AI 혁신생태계 조성 | B19: 전략분야 1) AI 고속도로 구축 | C19: 06 보건의료 AI 고도화와 AX 전환에 필요한 학습데이터 확충 | D19: 6-4 | E19: 보건의료 데이터플랫폼 연계 | F19: AI기본의료 소그룹 | G19: 과기정통부는 ‘국가데이터 통합플랫폼’을 통해 보건의료 학습데이터를 이용할 수 있도록 복지부의 보건의료 빅데이터 플랫폼과의 연계 및 협력 방안을 ’26년 1분기까지 마련한다. | H19: 26.1 | I19: 과기정통부 | K19: 복지부 | L19: AI인재양성지원팀 | M19: =IF($H19="기한없음","",DATE(2000+VALUE(LEFT($H19,2)),VALUE(RIGHT($H19,1))*3+1,1)-1) -> 46112 | N19: =IF($M19="","",$M19-이행현황요약!$B$3) -> -94 | O19: =IF($H19="기한없음","기한없음",IF($N19<0,"기한초과",IF($N19<=34,"긴급",IF($N19<=120,"주의",IF($N19<=240,"관찰","여유"))))) -> 기한초과 | P19: 진행중
A20: 1. AI 혁신생태계 조성 | B20: 전략분야 1) AI 고속도로 구축 | C20: 07 국가 과학 AI 통합 인프라 및 연구개발 혁신 생태계 구축 | D20: 7-1 | E20: K-문샷 추진전략 | F20: 과학 분과 | G20: 과기정통부는 AI를 활용한 과학혁신 가속화와 연구생산성의 획기적인 제고를 위해 ’26년 1분기까지 ‘K-문샷 추진 전략’을 수립한다. K-문샷 추진 전략은 ①연구데이터·GPU·AI모델·자율실험실 등 AI 핵심자원을 통합하는 국가과학AI통합플랫폼을 구축하고, ②전략 과학기술 분야와 핵심 난제를 선정하여 임무중심 R&D를 통해 해결하는 것을 목표로 한다. 전략 분야와 난제 해결 방식은 후술하는 행동계획 (14)번 “기초과학 및 전략 과학기술 분야 AI 혁신, AI 연구동료 개발”과 (29)번 “핵심 과학분야 AI파운데이션 모델 확보 및 공공·산업 확산”의 내용을 포함할 수 있다. | H20: 26.1 | I20: 과기정통부 | L20: AI인재양성지원팀 | M20: =IF($H20="기한없음","",DATE(2000+VALUE(LEFT($H20,2)),VALUE(RIGHT($H20,1))*3+1,1)-1) -> 46112 | N20: =IF($M20="","",$M20-이행현황요약!$B$3) -> -94 | O20: =IF($H20="기한없음","기한없음",IF($N20<0,"기한초과",IF($N20<=34,"긴급",IF($N20<=120,"주의",IF($N20<=240,"관찰","여유"))))) -> 기한초과 | P20: 진행중
A21: 1. AI 혁신생태계 조성 | B21: 전략분야 1) AI 고속도로 구축 | C21: 07 국가 과학 AI 통합 인프라 및 연구개발 혁신 생태계 구축 | D21: 7-2 | E21: 국가 연구데이터 수집·관리·활용 기반 구축 | F21: 과학 분과 | G21: 과기정통부는 국가연구개발사업을 통해 생산되는 연구데이터의 수집·관리·활용을 촉진하고, 이를 과학기술 AI 개발 및 고도화에 적극 활용할 수 있도록 제도적 기반을 마련한다. 이를 위해 연구 현장의 의견을 ’26년 1분기까지 폭넓게 수렴하고, 연구데이터의 정의·대상·책무를 명확히 규정하는 연구데이터법 제정이 원활히 추진될 수 있도록 지원한다. | H21: 26.1 | I21: 과기정통부 | L21: AI인재양성지원팀 | M21: =IF($H21="기한없음","",DATE(2000+VALUE(LEFT($H21,2)),VALUE(RIGHT($H21,1))*3+1,1)-1) -> 46112 | N21: =IF($M21="","",$M21-이행현황요약!$B$3) -> -94 | O21: =IF($H21="기한없음","기한없음",IF($N21<0,"기한초과",IF($N21<=34,"긴급",IF($N21<=120,"주의",IF($N21<=240,"관찰","여유"))))) -> 기한초과 | P21: 진행중
A22: 1. AI 혁신생태계 조성 | B22: 전략분야 1) AI 고속도로 구축 | C22: 07 국가 과학 AI 통합 인프라 및 연구개발 혁신 생태계 구축 | D22: 7-3 | E22: 국가 연구데이터 표준·품질 등 활용 체계 구축 | F22: 과학 분과 | G22: 과기정통부는 ’27년 4분기 이내에 국가 표준 메타데이터 체계와 데이터 품질 관리 기준을 단계적으로 수립하여 산·학·연이 국가 연구데이터를 효율적으로 활용할 수 있는 체계를 구축한다. 또한 연구데이터 기여도에 대한 인센티브 제도를 도입하고, 과제 기획 단계에서 수집 데이터의 범위와 내용을 함께 설계하도록 하여 연구데이터의 생산성과 활용성을 높인다. 아울러 연구데이터의 개방·공유·활용을 원칙으로 하되, 국가 경쟁력과 데이터 주권을 보장할 수 있는 보호 체계를 마련하고, 글로벌 연구데이터 협력 네트워크를 강화를 지원하여 연구자와 산업계가 해외 연구데이터에 접근·활용할 수 있는 기반을 조성한다. | H22: 27.4 | I22: 과기정통부 | L22: AI인재양성지원팀 | M22: =IF($H22="기한없음","",DATE(2000+VALUE(LEFT($H22,2)),VALUE(RIGHT($H22,1))*3+1,1)-1) -> 46752 | N22: =IF($M22="","",$M22-이행현황요약!$B$3) -> 546 | O22: =IF($H22="기한없음","기한없음",IF($N22<0,"기한초과",IF($N22<=34,"긴급",IF($N22<=120,"주의",IF($N22<=240,"관찰","여유"))))) -> 여유 | P22: 진행중
A23: 1. AI 혁신생태계 조성 | B23: 전략분야 1) AI 고속도로 구축 | C23: 07 국가 과학 AI 통합 인프라 및 연구개발 혁신 생태계 구축 | D23: 7-4 | E23: 과학기술 연구자 GPU 접근 지원 | F23: 과학 분과 | G23: 과기정통부는 과학기술 AI 연구 전용 GPU 확보 및 지원, 연구기관 간 GPU 공동 활용 체계 구축 등을 통해 과학기술 연구자들이 AI 융합 연구에 필요한 GPU 자원에 보다 원활하게 접근할 수 있도록 지원하는 정책을 ’26년 1분기까지 마련하고, 이후 단계적으로 추진한다. | H23: 26.1 | I23: 과기정통부 | L23: AI인재양성지원팀 | M23: =IF($H23="기한없음","",DATE(2000+VALUE(LEFT($H23,2)),VALUE(RIGHT($H23,1))*3+1,1)-1) -> 46112 | N23: =IF($M23="","",$M23-이행현황요약!$B$3) -> -94 | O23: =IF($H23="기한없음","기한없음",IF($N23<0,"기한초과",IF($N23<=34,"긴급",IF($N23<=120,"주의",IF($N23<=240,"관찰","여유"))))) -> 기한초과 | P23: 진행중
A24: 1. AI 혁신생태계 조성 | B24: 전략분야 1) AI 고속도로 구축 | C24: 07 국가 과학 AI 통합 인프라 및 연구개발 혁신 생태계 구축 | D24: 7-5 | E24: 국가과학AI연구소 설립 | F24: 과학 분과 | G24: 과기정통부는 공공 과학데이터와 공공 과학AI 모델을 중심으로 연구·산업·공공 확산의 산·학·연 생태계 허브 역할을 수행할 ‘(가칭)국가과학AI연구소’를 ’26년 1분기까지 설립한다. 이 연구소는 데이터 관리, 과학AI 플랫폼 운영, 프런티어 모델 개발을 담당하며, 국내외 기관과의 협력을 통해 국가 연구 성과가 산업 경쟁력 강화로 이어지도록 견인하는 중추적 역할을 수행한다. | H24: 26.1 | I24: 과기정통부 | L24: AI인재양성지원팀 | M24: =IF($H24="기한없음","",DATE(2000+VALUE(LEFT($H24,2)),VALUE(RIGHT($H24,1))*3+1,1)-1) -> 46112 | N24: =IF($M24="","",$M24-이행현황요약!$B$3) -> -94 | O24: =IF($H24="기한없음","기한없음",IF($N24<0,"기한초과",IF($N24<=34,"긴급",IF($N24<=120,"주의",IF($N24<=240,"관찰","여유"))))) -> 기한초과 | P24: 진행중
A25: 1. AI 혁신생태계 조성 | B25: 전략분야 1) AI 고속도로 구축 | C25: 08 국가 AI･데이터 거버넌스 정립 | D25: 8-1 | E25: 국가 AI·데이터 거버넌스 정립 | F25: 데이터 분과 | G25: 국가AI전략위는 민간･공공데이터의 관리와 활용 및 국가 차원의 인공지능 기술개발을 위한 인프라 구축, 인재 확보, 규제혁신의 실행 주체 및 의사결정 체계로서의 국가 CTO 체계 마련과 국가 CDO 체계 정비, 국가 CTO-CAIO-CDO 간의 역할 구분 및 유기적 협업 등이 포함된 종합계획을 ’26년 2분기 이내에 마련한다. | H25: 26.2 | I25: 국가AI전략위 | L25: AI데이터규제혁신팀 | M25: =IF($H25="기한없음","",DATE(2000+VALUE(LEFT($H25,2)),VALUE(RIGHT($H25,1))*3+1,1)-1) -> 46203 | N25: =IF($M25="","",$M25-이행현황요약!$B$3) -> -3 | O25: =IF($H25="기한없음","기한없음",IF($N25<0,"기한초과",IF($N25<=34,"긴급",IF($N25<=120,"주의",IF($N25<=240,"관찰","여유"))))) -> 기한초과 | P25: 진행중
A26: 1. AI 혁신생태계 조성 | B26: 전략분야 1) AI 고속도로 구축 | C26: 08 국가 AI･데이터 거버넌스 정립 | D26: 8-2 | E26: 국가 AI·데이터 거버넌스 제도화 | F26: 데이터 분과 | G26: 부총리인 과기정통부를 중심으로 행안부, 산업부, 국가데이터처를 포함한 관계 부처는 국가AI전략위가 마련한 종합계획에 따른 거버넌스 실행계획을 ’26년 3분기까지 마련하고 관련 법령 개정안을 정부안으로 마련하여 ’26년 4분기까지 국회에 제출한다. | H26: 26.3 | I26: 과기정통부 | K26: 국가AI전략위, 국가데이터처, 산업부, 행안부 | L26: AI데이터규제혁신팀 | M26: =IF($H26="기한없음","",DATE(2000+VALUE(LEFT($H26,2)),VALUE(RIGHT($H26,1))*3+1,1)-1) -> 46295 | N26: =IF($M26="","",$M26-이행현황요약!$B$3) -> 89 | O26: =IF($H26="기한없음","기한없음",IF($N26<0,"기한초과",IF($N26<=34,"긴급",IF($N26<=120,"주의",IF($N26<=240,"관찰","여유"))))) -> 주의 | P26: 진행중
A27: 1. AI 혁신생태계 조성 | B27: 전략분야 1) AI 고속도로 구축 | C27: 08 국가 AI･데이터 거버넌스 정립 | D27: 8-3 | E27: 국가 CTO 체계 운영 | F27: 데이터 분과 | G27: 법령 개정을 통한 거버넌스 종합 개편이 완료되기 이전까지 과기정통부는 과학기술부총리로서 관련 대통령령(예: 국가 CTO 설치 및 운영 규정)을 신설하여 국가 CTO 체계를 운영한다. | H27: 기한없음 | I27: 과기정통부 | L27: AI데이터규제혁신팀 | M27: =IF($H27="기한없음","",DATE(2000+VALUE(LEFT($H27,2)),VALUE(RIGHT($H27,1))*3+1,1)-1) | N27: =IF($M27="","",$M27-이행현황요약!$B$3) | O27: =IF($H27="기한없음","기한없음",IF($N27<0,"기한초과",IF($N27<=34,"긴급",IF($N27<=120,"주의",IF($N27<=240,"관찰","여유"))))) -> 기한없음 | P27: 진행중
A28: 1. AI 혁신생태계 조성 | B28: 전략분야 1) AI 고속도로 구축 | C28: 09 민간·공공 AI 보안 생태계 활성화 및 정보보호산업 자생력 확보 | D28: 9-1 | E28: 정보보호 인증체계와 연계한 기업 보안 취약점 파악·관리 강화 | F28: 보안 특위 | G28: 과기정통부는 개인정보위와 협력하여 ISMS 인증 및 ISMS-P 인증 체계안에 기업의 IT 자산에 대한 취약점 파악 및 관리가 가능하도록 하는‘공격 표면 관리 점검’ 방법을 ’26년 2분기까지 반영하도록 한다. | H28: 26.2 | I28: 과기정통부 | K28: 개인정보위 | L28: AI데이터규제혁신팀 | M28: =IF($H28="기한없음","",DATE(2000+VALUE(LEFT($H28,2)),VALUE(RIGHT($H28,1))*3+1,1)-1) -> 46203 | N28: =IF($M28="","",$M28-이행현황요약!$B$3) -> -3 | O28: =IF($H28="기한없음","기한없음",IF($N28<0,"기한초과",IF($N28<=34,"긴급",IF($N28<=120,"주의",IF($N28<=240,"관찰","여유"))))) -> 기한초과 | P28: 진행중
A29: 1. AI 혁신생태계 조성 | B29: 전략분야 1) AI 고속도로 구축 | C29: 09 민간·공공 AI 보안 생태계 활성화 및 정보보호산업 자생력 확보 | D29: 9-10 | E29: AI 보안 유망기업 집중 육성 | F29: 보안 특위 | G29: 과기정통부는 차세대 AI 기술(예: AI 에이전트, 물리형 AI 등)의 보안을 책임질 유망기업을 대상으로 R&D 자금지원, 시제품 개발·검증, 보안 인증 및 규제 대응 컨설팅, 시장·해외진출 지원 등을 포함한 집중 육성 프로그램을 운영한다. 또한, 금융·제조·의료 등 산업별로 특화된 보안기업을 선정하여, 기획-개발-시험-사업화-고도화에 이르는 전 주기 지원체계를 제공한다. 아울러, 이러한 기업의 시험·검증·실증을 뒷받침하기 위한 ‘통합 보안 지원센터’를 ’26년 4분기까지 구축한다. | H29: 26.4 | I29: 과기정통부 | L29: AI데이터규제혁신팀 | M29: =IF($H29="기한없음","",DATE(2000+VALUE(LEFT($H29,2)),VALUE(RIGHT($H29,1))*3+1,1)-1) -> 46387 | N29: =IF($M29="","",$M29-이행현황요약!$B$3) -> 181 | O29: =IF($H29="기한없음","기한없음",IF($N29<0,"기한초과",IF($N29<=34,"긴급",IF($N29<=120,"주의",IF($N29<=240,"관찰","여유"))))) -> 관찰 | P29: 진행중
A30: 1. AI 혁신생태계 조성 | B30: 전략분야 1) AI 고속도로 구축 | C30: 09 민간·공공 AI 보안 생태계 활성화 및 정보보호산업 자생력 확보 | D30: 9-2 | E30: 보안 취약점 신고·조치·공개 제도(CVD/VDP) 도입 로드맵 마련 | F30: 보안 특위 | G30: 국가AI전략위는 기존 사후 대응의 한계를 넘어 사전적이고 상시적인 정보통신망 보안 제도로의 패러다임 변화를 위해 美, EU가 이미 채택·운영 중인 취약점 신고·조치·공개 제도(CVD/VDP, Coordinated Vulnerability Disclosure/ Vulnerability Disclosure Policy)에 대한 국내 민간·공공 도입 로드맵을 ‘26년 1분기까지 마련한다. | H30: 26.1 | I30: 국가AI전략위 | L30: AI데이터규제혁신팀 | M30: =IF($H30="기한없음","",DATE(2000+VALUE(LEFT($H30,2)),VALUE(RIGHT($H30,1))*3+1,1)-1) -> 46112 | N30: =IF($M30="","",$M30-이행현황요약!$B$3) -> -94 | O30: =IF($H30="기한없음","기한없음",IF($N30<0,"기한초과",IF($N30<=34,"긴급",IF($N30<=120,"주의",IF($N30<=240,"관찰","여유"))))) -> 기한초과 | P30: 진행중
A31: 1. AI 혁신생태계 조성 | B31: 전략분야 1) AI 고속도로 구축 | C31: 09 민간·공공 AI 보안 생태계 활성화 및 정보보호산업 자생력 확보 | D31: 9-3 | E31: 화이트해커 활용 취약점 사전 발굴사업 시범 운영 | F31: 보안 특위 | G31: 과기정통부와 국정원은 화이트해커가 민간·공공분야 정보통신망 서비스 및 디지털 제품(소프트웨어, 하드웨어 등)의 보안 취약점을 사전에 발굴하는 활동을 합법적으로 수행할 수 있도록 해당 활동에 참여하는 피대상 기업·기관(공공기관 포함)을 지속 확대하는 한편, 참여 피대상 기업·기관을 대상으로 하는 시범사업을 ’26년 4분기까지 우선 진행한다. | H31: 26.4 | I31: 과기정통부, 국정원 | J31: O | L31: AI데이터규제혁신팀 | M31: =IF($H31="기한없음","",DATE(2000+VALUE(LEFT($H31,2)),VALUE(RIGHT($H31,1))*3+1,1)-1) -> 46387 | N31: =IF($M31="","",$M31-이행현황요약!$B$3) -> 181 | O31: =IF($H31="기한없음","기한없음",IF($N31<0,"기한초과",IF($N31<=34,"긴급",IF($N31<=120,"주의",IF($N31<=240,"관찰","여유"))))) -> 관찰 | P31: 진행중
A32: 1. AI 혁신생태계 조성 | B32: 전략분야 1) AI 고속도로 구축 | C32: 09 민간·공공 AI 보안 생태계 활성화 및 정보보호산업 자생력 확보 | D32: 9-4 | E32: CVD/VDP 가이드라인 마련 및 참여 촉진 | F32: 보안 특위 | G32: 과기정통부와 국정원은 국가AI전략위가 마련한 로드맵에 따라 유관기관과 협력하여 민간·공공분야 정보통신망 서비스 및 디지털 제품의 보안 취약점을 효과적으로 발굴, 신고, 조치, 공개하는 협력적 가이드라인과 화이트해커의 참여 촉진 방안을 ’26년 4분기까지 마련하고 CVD/VDP 관리 전문 기관을 지정한다. | H32: 26.4 | I32: 과기정통부, 국정원 | J32: O | K32: 국가AI전략위 | L32: AI데이터규제혁신팀 | M32: =IF($H32="기한없음","",DATE(2000+VALUE(LEFT($H32,2)),VALUE(RIGHT($H32,1))*3+1,1)-1) -> 46387 | N32: =IF($M32="","",$M32-이행현황요약!$B$3) -> 181 | O32: =IF($H32="기한없음","기한없음",IF($N32<0,"기한초과",IF($N32<=34,"긴급",IF($N32<=120,"주의",IF($N32<=240,"관찰","여유"))))) -> 관찰 | P32: 진행중
A33: 1. AI 혁신생태계 조성 | B33: 전략분야 1) AI 고속도로 구축 | C33: 09 민간·공공 AI 보안 생태계 활성화 및 정보보호산업 자생력 확보 | D33: 9-5 | E33: CVD/VDP 운영 기관 인센티브 부여 | F33: 보안 특위 | G33: 과기정통부, 국정원, 기획예산처, 조달청, 개인정보위는 디지털 제품 및 서비스에 대한 취약점 발굴·신고·공개 정책을 운영하는 민간기업·공공기관에 대해 보안인증 가점, 실태평가 연계, 제도운영 예산 확보 지원, 정부 사업 입찰 우대, 사고 발생시 과징금 경감 등 다양한 인센티브를 제공하는 방안을 ’26년 4분기까지 마련한다. | H33: 26.4 | I33: 과기정통부, 국정원 | J33: O | K33: 개인정보위, 기획처, 조달청 | L33: AI데이터규제혁신팀 | M33: =IF($H33="기한없음","",DATE(2000+VALUE(LEFT($H33,2)),VALUE(RIGHT($H33,1))*3+1,1)-1) -> 46387 | N33: =IF($M33="","",$M33-이행현황요약!$B$3) -> 181 | O33: =IF($H33="기한없음","기한없음",IF($N33<0,"기한초과",IF($N33<=34,"긴급",IF($N33<=120,"주의",IF($N33<=240,"관찰","여유"))))) -> 관찰 | P33: 진행중
A34: 1. AI 혁신생태계 조성 | B34: 전략분야 1) AI 고속도로 구축 | C34: 09 민간·공공 AI 보안 생태계 활성화 및 정보보호산업 자생력 확보 | D34: 9-6 | E34: CVD/VDP 민간·공공 제도화 | F34: 보안 특위 | G34: 과기정통부와 국정원은 ’26년 4분기까지 수행된 시범사업 등의 결과를 바탕으로 민간·공공에 걸친 CVD/VDP 제도화를 위한 관련 법·제도 개선을 ’27년 내 추진하며 법무부, 문체부, 개인정보위 등 관계부처는 이를 위한 소관 법률, 관계 하위법령 개정 등에 협조한다. | H34: 27.4 | I34: 과기정통부, 국정원 | J34: O | K34: 개인정보위, 문체부, 법무부 | L34: AI데이터규제혁신팀 | M34: =IF($H34="기한없음","",DATE(2000+VALUE(LEFT($H34,2)),VALUE(RIGHT($H34,1))*3+1,1)-1) -> 46752 | N34: =IF($M34="","",$M34-이행현황요약!$B$3) -> 546 | O34: =IF($H34="기한없음","기한없음",IF($N34<0,"기한초과",IF($N34<=34,"긴급",IF($N34<=120,"주의",IF($N34<=240,"관찰","여유"))))) -> 여유 | P34: 진행중
A35: 1. AI 혁신생태계 조성 | B35: 전략분야 1) AI 고속도로 구축 | C35: 09 민간·공공 AI 보안 생태계 활성화 및 정보보호산업 자생력 확보 | D35: 9-7 | E35: 중소기업 AI 보안 솔루션 자체 개발 및 국산 솔루션 활용 지원 | F35: 보안 특위 | G35: 과기정통부는 재정경제부와 협력해 중소기업의 국산 AI 보안 솔루션 도입 및 신규 보안 기술 R&D에 대한 세제지원을 통해 외산 의존도를 낮추고 국내 기업의 기술개발을 촉진하는 정책을 신속히 마련하고, ’27년 1분기까지 단계적으로 추진한다. | H35: 27.1 | I35: 과기정통부 | K35: 재경부 | L35: AI데이터규제혁신팀 | M35: =IF($H35="기한없음","",DATE(2000+VALUE(LEFT($H35,2)),VALUE(RIGHT($H35,1))*3+1,1)-1) -> 46477 | N35: =IF($M35="","",$M35-이행현황요약!$B$3) -> 271 | O35: =IF($H35="기한없음","기한없음",IF($N35<0,"기한초과",IF($N35<=34,"긴급",IF($N35<=120,"주의",IF($N35<=240,"관찰","여유"))))) -> 여유 | P35: 진행중
A36: 1. AI 혁신생태계 조성 | B36: 전략분야 1) AI 고속도로 구축 | C36: 09 민간·공공 AI 보안 생태계 활성화 및 정보보호산업 자생력 확보 | D36: 9-8 | E36: 사이버 보안 펀드 확대 및 지원 강화 | F36: 보안 특위 | G36: 과기정통부는 AI 보안 생태계 활성화를 위해 사이버 보안 펀드를 확대하고, 중기부와 협력해 중소·영세기업의 AI 보안 솔루션 도입을 지원해 ’26년 4분기까지 국가 전반의 보안 수준을 제고한다. | H36: 26.4 | I36: 과기정통부 | K36: 중기부 | L36: AI데이터규제혁신팀 | M36: =IF($H36="기한없음","",DATE(2000+VALUE(LEFT($H36,2)),VALUE(RIGHT($H36,1))*3+1,1)-1) -> 46387 | N36: =IF($M36="","",$M36-이행현황요약!$B$3) -> 181 | O36: =IF($H36="기한없음","기한없음",IF($N36<0,"기한초과",IF($N36<=34,"긴급",IF($N36<=120,"주의",IF($N36<=240,"관찰","여유"))))) -> 관찰 | P36: 진행중
A37: 1. AI 혁신생태계 조성 | B37: 전략분야 1) AI 고속도로 구축 | C37: 09 민간·공공 AI 보안 생태계 활성화 및 정보보호산업 자생력 확보 | D37: 9-9 | E37: 중소기업 AI 보안 역량 강화(긴급복구 지원 등) | F37: 보안 특위 | G37: 과기정통부는 기획예산처와 협력하여 ’26년 4분기까지 AI 시스템에 대한 공격(AI 모델 오염·데이터 유출·프롬프트 인젝션 등), AI를 이용한 공격(AI 특화 침해사고, AI 기반 악성코드·딥페이크 공격 등)으로 피해를 입은 중소기업에 대한 긴급 복구 지원을 제공하고, 동시에 AI 보안 전문인력·도구·가이드 제공 등 역량 확보 프로그램을 지원한다. 중소기업 대상 AI 보안 솔루션 구매, AI 취약점 점검 서비스, 클라우드 기반 AI 보안 서비스(AI-SECaaS) 구독료 지원 등의 사업을 추진하여 AI 보안 사각지대를 해소하고 국내 AI 보안 산업 생태계의 선순환 구조를 만든다. | H37: 26.4 | I37: 과기정통부 | K37: 기획처 | L37: AI데이터규제혁신팀 | M37: =IF($H37="기한없음","",DATE(2000+VALUE(LEFT($H37,2)),VALUE(RIGHT($H37,1))*3+1,1)-1) -> 46387 | N37: =IF($M37="","",$M37-이행현황요약!$B$3) -> 181 | O37: =IF($H37="기한없음","기한없음",IF($N37<0,"기한초과",IF($N37<=34,"긴급",IF($N37<=120,"주의",IF($N37<=240,"관찰","여유"))))) -> 관찰 | P37: 진행중
A38: 1. AI 혁신생태계 조성 | B38: 전략분야 1) AI 고속도로 구축 | C38: 10 AI 기반의 사이버 보안 체계 구축, AI 보안 기술 경쟁력 강화 및 보안 전문 인재 양성 | D38: 10-1 | E38: K-사이버 보안 LLM 구축 | F38: 보안 특위 | G38: 과기정통부는 글로벌 빅테크 기업의 범용 LLM에 대한 기술 종속을 탈피하고 국내 민감 위협 정보의 외부 유출을 방지하기 위해, 한국의 사이버 위협 환경에서 알려진 위협 및 알려지지 않은 신종·변종 위협의 분석이 가능한 ‘K-사이버 보안 LLM’을 구축한다. K-사이버 보안 LLM의 지속 학습과 ‘사후 대응’에서 ‘예측·예방’으로의 전환을 위해, 국정원 등 관계 부처와 협력하여 정부 및 공공기관에 AI 기반의 이상(anomaly) 탐지 체계를 구축하고 이를 통해 징후가 포착된 알려지지 않은 신종·변종 위협 데이터를 정제하여 K-사이버 보안 LLM의 학습데이터로 반영하고, 이를 기반으로 ‘탐지→분석→학습’ 과정을 반복하여 알려지지 않은 위협의 사전 징후 분석과 대응의 정확도 및 신뢰도가 향상되는 체계를 구축하고 적용하는 방안을 ’26년 2분기까지 수립하고 ’26년부터 추진한다. | H38: 26.2 | I38: 과기정통부 | K38: 국정원 | L38: AI데이터규제혁신팀 | M38: =IF($H38="기한없음","",DATE(2000+VALUE(LEFT($H38,2)),VALUE(RIGHT($H38,1))*3+1,1)-1) -> 46203 | N38: =IF($M38="","",$M38-이행현황요약!$B$3) -> -3 | O38: =IF($H38="기한없음","기한없음",IF($N38<0,"기한초과",IF($N38<=34,"긴급",IF($N38<=120,"주의",IF($N38<=240,"관찰","여유"))))) -> 기한초과 | P38: 진행중
A39: 1. AI 혁신생태계 조성 | B39: 전략분야 1) AI 고속도로 구축 | C39: 10 AI 기반의 사이버 보안 체계 구축, AI 보안 기술 경쟁력 강화 및 보안 전문 인재 양성 | D39: 10-2 | E39: 민간주도 AI 정보공유 분석센터 설립 | F39: 보안 특위 | G39: 과기정통부는 AI 보안 위협 대응을 위한 민간 주도 AI 정보 공유 분석센터(AI-ISAC)를 ’26년 4분기까지 설립하고, 향후 개발 및 적용 예정인 독자적인 AI 모델을 상시 점검하는 체계를 ’26년 4분기까지 구축한다. | H39: 26.4 | I39: 과기정통부 | L39: AI데이터규제혁신팀 | M39: =IF($H39="기한없음","",DATE(2000+VALUE(LEFT($H39,2)),VALUE(RIGHT($H39,1))*3+1,1)-1) -> 46387 | N39: =IF($M39="","",$M39-이행현황요약!$B$3) -> 181 | O39: =IF($H39="기한없음","기한없음",IF($N39<0,"기한초과",IF($N39<=34,"긴급",IF($N39<=120,"주의",IF($N39<=240,"관찰","여유"))))) -> 관찰 | P39: 진행중
A40: 1. AI 혁신생태계 조성 | B40: 전략분야 1) AI 고속도로 구축 | C40: 10 AI 기반의 사이버 보안 체계 구축, AI 보안 기술 경쟁력 강화 및 보안 전문 인재 양성 | D40: 10-3 | E40: 차세대 AI 보안 R&D 투자 확대 | F40: 보안 특위 | G40: 과기정통부는 AI 모델·시스템의 보안 내재화, AI 기반 공격 탐지 및 방어, 양자 내성 암호 전환 등 차세대 보안 기술 주도권을 확보하기 위해 AI, 양자 등 차세대 보안 기술 개발 투자를 전체 R&D 예산의 3% 수준으로 ’30년까지 대폭 확대한다. | H40: 30.4 | I40: 과기정통부 | L40: AI데이터규제혁신팀 | M40: =IF($H40="기한없음","",DATE(2000+VALUE(LEFT($H40,2)),VALUE(RIGHT($H40,1))*3+1,1)-1) -> 47848 | N40: =IF($M40="","",$M40-이행현황요약!$B$3) -> 1642 | O40: =IF($H40="기한없음","기한없음",IF($N40<0,"기한초과",IF($N40<=34,"긴급",IF($N40<=120,"주의",IF($N40<=240,"관찰","여유"))))) -> 여유 | P40: 진행중
...
